<?xml version="1.0" ?>
<!-- =================================================================================== -->
<!-- |    This document was autogenerated by xacro from models/scout/model.xacro       | -->
<!-- |    EDITING THIS FILE BY HAND IS NOT RECOMMENDED                                 | -->
<!-- =================================================================================== -->
<sdf version="1.10">
  <model canonical_link="chassis" name="scout">
    <!-- base_link -->
    <link name="chassis">
      <pose relative_to="__model__">0 0 1 0 0 0</pose>
      <inertial auto="true">
        <mass>50</mass>
      </inertial>
      <visual name="visual">
        <geometry>
          <mesh>
            <uri>meshes/scout_base.dae</uri>
          </mesh>
        </geometry>
      </visual>
      <collision name="collision">
        <geometry>
          <box>
            <size>0.93 0.42 0.19</size>
          </box>
        </geometry>
      </collision>
      <sensor name="imu_sensor" type="imu">
        <always_on>true</always_on>
        <update_rate>1</update_rate>
        <visualize>true</visualize>
        <topic>scout/imu</topic>
      </sensor>
    </link>
    <!-- wheels -->
    <link name="front_left_wheel">
      <pose relative_to="chassis">0.249 0.29153 -0.0702 0.0 0.0 0.0</pose>
      <inertial auto="true">
        <mass>8</mass>
      </inertial>
      <visual name="visual">
        <geometry>
          <mesh>
            <uri>meshes/wheel_type2.dae</uri>
          </mesh>
        </geometry>
      </visual>
      <collision name="collision">
        <pose relative_to="chassis">0.249 0.29153 -0.0702 1.5707963267948966 0.0 0.0</pose>
        <geometry>
          <cylinder>
            <radius>0.16</radius>
            <length>0.11</length>
          </cylinder>
        </geometry>
      </collision>
    </link>
    <joint name="front_left_wheel_joint" type="revolute">
      <pose relative_to="front_left_wheel"/>
      <parent>chassis</parent>
      <child>front_left_wheel</child>
      <axis>
        <xyz expressed_in="__model__">0 1 0</xyz>
        <limit>
          <lower>-inf</lower>
          <upper>inf</upper>
        </limit>
      </axis>
    </joint>
    <link name="front_right_wheel">
      <pose relative_to="chassis">0.249 -0.29153 -0.0702 3.141592653589793 0.0 0.0</pose>
      <inertial auto="true">
        <mass>8</mass>
      </inertial>
      <visual name="visual">
        <geometry>
          <mesh>
            <uri>meshes/wheel_type1.dae</uri>
          </mesh>
        </geometry>
      </visual>
      <collision name="collision">
        <pose relative_to="chassis">0.249 -0.29153 -0.0702 -1.5707963267948966 0.0 0.0</pose>
        <geometry>
          <cylinder>
            <radius>0.16</radius>
            <length>0.11</length>
          </cylinder>
        </geometry>
      </collision>
    </link>
    <joint name="front_right_wheel_joint" type="revolute">
      <pose relative_to="front_right_wheel"/>
      <parent>chassis</parent>
      <child>front_right_wheel</child>
      <axis>
        <xyz expressed_in="__model__">0 1 0</xyz>
        <limit>
          <lower>-inf</lower>
          <upper>inf</upper>
        </limit>
      </axis>
    </joint>
    <link name="back_left_wheel">
      <pose relative_to="chassis">-0.249 0.29153 -0.0702 0.0 0.0 0.0</pose>
      <inertial auto="true">
        <mass>8</mass>
      </inertial>
      <visual name="visual">
        <geometry>
          <mesh>
            <uri>meshes/wheel_type1.dae</uri>
          </mesh>
        </geometry>
      </visual>
      <collision name="collision">
        <pose relative_to="chassis">-0.249 0.29153 -0.0702 1.5707963267948966 0.0 0.0</pose>
        <geometry>
          <cylinder>
            <radius>0.16</radius>
            <length>0.11</length>
          </cylinder>
        </geometry>
      </collision>
    </link>
    <joint name="back_left_wheel_joint" type="revolute">
      <pose relative_to="back_left_wheel"/>
      <parent>chassis</parent>
      <child>back_left_wheel</child>
      <axis>
        <xyz expressed_in="__model__">0 1 0</xyz>
        <limit>
          <lower>-inf</lower>
          <upper>inf</upper>
        </limit>
      </axis>
    </joint>
    <link name="back_right_wheel">
      <pose relative_to="chassis">-0.249 -0.29153 -0.0702 3.141592653589793 0.0 0.0</pose>
      <inertial auto="true">
        <mass>8</mass>
      </inertial>
      <visual name="visual">
        <geometry>
          <mesh>
            <uri>meshes/wheel_type2.dae</uri>
          </mesh>
        </geometry>
      </visual>
      <collision name="collision">
        <pose relative_to="chassis">-0.249 -0.29153 -0.0702 -1.5707963267948966 0.0 0.0</pose>
        <geometry>
          <cylinder>
            <radius>0.16</radius>
            <length>0.11</length>
          </cylinder>
        </geometry>
      </collision>
    </link>
    <joint name="back_right_wheel_joint" type="revolute">
      <pose relative_to="back_right_wheel"/>
      <parent>chassis</parent>
      <child>back_right_wheel</child>
      <axis>
        <xyz expressed_in="__model__">0 1 0</xyz>
        <limit>
          <lower>-inf</lower>
          <upper>inf</upper>
        </limit>
      </axis>
    </joint>
    <!-- visual connection -->
    <link name="force_bar_connection_visual">
      <visual name="force_bar_connection_visual_center_bar_left">
        <pose relative_to="chassis">0.4 0.04 0 0 0 0</pose>
        <geometry>
          <box>
            <size>0.2 0.025 0.025</size>
          </box>
        </geometry>
        <material>
          <ambient>0.25 0.25 0.25 1.0</ambient>
          <diffuse>0.25 0.25 0.25 1.0</diffuse>
          <specular>0.25 0.25 0.25 1.0</specular>
        </material>
      </visual>
      <visual name="force_bar_connection_visual_center_bar_right">
        <pose relative_to="chassis">0.4 -0.04 0 0 0 0</pose>
        <geometry>
          <box>
            <size>0.2 0.025 0.025</size>
          </box>
        </geometry>
        <material>
          <ambient>0.25 0.25 0.25 1.0</ambient>
          <diffuse>0.25 0.25 0.25 1.0</diffuse>
          <specular>0.25 0.25 0.25 1.0</specular>
        </material>
      </visual>
      <visual name="force_bar_connection_visual_front_bar_top">
        <pose relative_to="chassis">0.4875 0 0 0 0 0</pose>
        <geometry>
          <box>
            <size>0.025 0.41 0.025</size>
          </box>
        </geometry>
        <material>
          <ambient>0.25 0.25 0.25 1.0</ambient>
          <diffuse>0.25 0.25 0.25 1.0</diffuse>
          <specular>0.25 0.25 0.25 1.0</specular>
        </material>
      </visual>
      <visual name="force_bar_connection_visual_front_bar_left">
        <pose relative_to="chassis">0.4575 0.265 0 0 0 0.43633</pose>
        <geometry>
          <box>
            <size>0.025 0.15 0.025</size>
          </box>
        </geometry>
        <material>
          <ambient>0.25 0.25 0.25 1.0</ambient>
          <diffuse>0.25 0.25 0.25 1.0</diffuse>
          <specular>0.25 0.25 0.25 1.0</specular>
        </material>
      </visual>
      <visual name="force_bar_connection_visual_front_bar_right">
        <pose relative_to="chassis">0.4575 -0.265 0 0 0 -0.43633</pose>
        <geometry>
          <box>
            <size>0.025 0.15 0.025</size>
          </box>
        </geometry>
        <material>
          <ambient>0.25 0.25 0.25 1.0</ambient>
          <diffuse>0.25 0.25 0.25 1.0</diffuse>
          <specular>0.25 0.25 0.25 1.0</specular>
        </material>
      </visual>
    </link>
    <joint name="force_bar_connection_visual_joint" type="fixed">
      <pose relative_to="force_bar_connection_visual"/>
      <parent>chassis</parent>
      <child>force_bar_connection_visual</child>
    </joint>
    <!-- sensor bar -->
    <link name="force_bar_P0_link">
      <pose relative_to="chassis">0.466 0.28 0.0 1.5707963267948966 0.0 0.43633</pose>
      <inertial auto="true">
        <mass>1</mass>
      </inertial>
      <visual name="visual">
        <geometry>
          <box>
            <size>0.005 0.15 0.14</size>
          </box>
        </geometry>
        <material>
          <ambient>0.25 0.25 0.25 1.0</ambient>
          <diffuse>0.25 0.25 0.25 1.0</diffuse>
          <specular>0.25 0.25 0.25 1.0</specular>
        </material>
      </visual>
      <collision name="collision">
        <geometry>
          <box>
            <size>0.005 0.15 0.14</size>
          </box>
        </geometry>
      </collision>
    </link>
    <joint name="force_bar_P0_joint" type="fixed">
      <pose relative_to="force_bar_P0_link"/>
      <parent>chassis</parent>
      <child>force_bar_P0_link</child>
      <sensor name="force_bar_P0_sensor" type="force_torque">
        <always_on>true</always_on>
        <update_rate>1000</update_rate>
        <visualize>true</visualize>
        <topic>/scout/force_bar/segment_0</topic>
      </sensor>
    </joint>
    <link name="force_bar_P1_link">
      <pose relative_to="chassis">0.5 0.14 0.0 1.5707963267948966 0.0 0.0</pose>
      <inertial auto="true">
        <mass>1</mass>
      </inertial>
      <visual name="visual">
        <geometry>
          <box>
            <size>0.005 0.15 0.13</size>
          </box>
        </geometry>
        <material>
          <ambient>0.25 0.25 0.25 1.0</ambient>
          <diffuse>0.25 0.25 0.25 1.0</diffuse>
          <specular>0.25 0.25 0.25 1.0</specular>
        </material>
      </visual>
      <collision name="collision">
        <geometry>
          <box>
            <size>0.005 0.15 0.13</size>
          </box>
        </geometry>
      </collision>
    </link>
    <joint name="force_bar_P1_joint" type="fixed">
      <pose relative_to="force_bar_P1_link"/>
      <parent>chassis</parent>
      <child>force_bar_P1_link</child>
      <sensor name="force_bar_P1_sensor" type="force_torque">
        <always_on>true</always_on>
        <update_rate>1000</update_rate>
        <visualize>true</visualize>
        <topic>/scout/force_bar/segment_1</topic>
      </sensor>
    </joint>
    <link name="force_bar_P2_link">
      <pose relative_to="chassis">0.5 0.0 0.0 1.5707963267948966 0.0 0.0</pose>
      <inertial auto="true">
        <mass>1</mass>
      </inertial>
      <visual name="visual">
        <geometry>
          <box>
            <size>0.005 0.15 0.13</size>
          </box>
        </geometry>
        <material>
          <ambient>0.25 0.25 0.25 1.0</ambient>
          <diffuse>0.25 0.25 0.25 1.0</diffuse>
          <specular>0.25 0.25 0.25 1.0</specular>
        </material>
      </visual>
      <collision name="collision">
        <geometry>
          <box>
            <size>0.005 0.15 0.13</size>
          </box>
        </geometry>
      </collision>
    </link>
    <joint name="force_bar_P2_joint" type="fixed">
      <pose relative_to="force_bar_P2_link"/>
      <parent>chassis</parent>
      <child>force_bar_P2_link</child>
      <sensor name="force_bar_P2_sensor" type="force_torque">
        <always_on>true</always_on>
        <update_rate>1000</update_rate>
        <visualize>true</visualize>
        <topic>/scout/force_bar/segment_2</topic>
      </sensor>
    </joint>
    <link name="force_bar_P3_link">
      <pose relative_to="chassis">0.5 -0.14 0.0 1.5707963267948966 0.0 0.0</pose>
      <inertial auto="true">
        <mass>1</mass>
      </inertial>
      <visual name="visual">
        <geometry>
          <box>
            <size>0.005 0.15 0.13</size>
          </box>
        </geometry>
        <material>
          <ambient>0.25 0.25 0.25 1.0</ambient>
          <diffuse>0.25 0.25 0.25 1.0</diffuse>
          <specular>0.25 0.25 0.25 1.0</specular>
        </material>
      </visual>
      <collision name="collision">
        <geometry>
          <box>
            <size>0.005 0.15 0.13</size>
          </box>
        </geometry>
      </collision>
    </link>
    <joint name="force_bar_P3_joint" type="fixed">
      <pose relative_to="force_bar_P3_link"/>
      <parent>chassis</parent>
      <child>force_bar_P3_link</child>
      <sensor name="force_bar_P3_sensor" type="force_torque">
        <always_on>true</always_on>
        <update_rate>1000</update_rate>
        <visualize>true</visualize>
        <topic>/scout/force_bar/segment_3</topic>
      </sensor>
    </joint>
    <link name="force_bar_P4_link">
      <pose relative_to="chassis">0.466 -0.28 0.0 1.5707963267948966 0.0 -0.43633</pose>
      <inertial auto="true">
        <mass>1</mass>
      </inertial>
      <visual name="visual">
        <geometry>
          <box>
            <size>0.005 0.15 0.14</size>
          </box>
        </geometry>
        <material>
          <ambient>0.25 0.25 0.25 1.0</ambient>
          <diffuse>0.25 0.25 0.25 1.0</diffuse>
          <specular>0.25 0.25 0.25 1.0</specular>
        </material>
      </visual>
      <collision name="collision">
        <geometry>
          <box>
            <size>0.005 0.15 0.14</size>
          </box>
        </geometry>
      </collision>
    </link>
    <joint name="force_bar_P4_joint" type="fixed">
      <pose relative_to="force_bar_P4_link"/>
      <parent>chassis</parent>
      <child>force_bar_P4_link</child>
      <sensor name="force_bar_P4_sensor" type="force_torque">
        <always_on>true</always_on>
        <update_rate>1000</update_rate>
        <visualize>true</visualize>
        <topic>/scout/force_bar/segment_4</topic>
      </sensor>
    </joint>
    <!-- plugins -->
    <plugin filename="gz-sim-mecanum-drive-system" name="gz::sim::systems::MecanumDrive">
      <front_left_joint>front_left_wheel_joint</front_left_joint>
      <front_right_joint>front_right_wheel_joint</front_right_joint>
      <back_left_joint>back_left_wheel_joint</back_left_joint>
      <back_right_joint>back_right_wheel_joint</back_right_joint>
      <wheelbase>0.498</wheelbase>
      <wheel_separation>0.58306</wheel_separation>
      <wheel_radius>0.16</wheel_radius>
      <odom_publish_frequency>1</odom_publish_frequency>
      <topic>cmd_vel</topic>
    </plugin>
    <plugin filename="gz-sim-triggered-publisher-system" name="gz::sim::systems::TriggeredPublisher">
      <input topic="/keyboard/keypress" type="gz.msgs.Int32">
        <match field="data">16777235</match>
      </input>
      <output topic="/cmd_vel" type="gz.msgs.Twist">
        linear: {x: 0.5}, angular: {z: 0.0}
      </output>
    </plugin>
    <plugin filename="gz-sim-triggered-publisher-system" name="gz::sim::systems::TriggeredPublisher">
      <input topic="/keyboard/keypress" type="gz.msgs.Int32">
        <match field="data">16777237</match>
      </input>
      <output topic="/cmd_vel" type="gz.msgs.Twist">
        linear: {x: -0.5}, angular: {z: 0.0}
      </output>
    </plugin>
    <plugin filename="gz-sim-triggered-publisher-system" name="gz::sim::systems::TriggeredPublisher">
      <input topic="/keyboard/keypress" type="gz.msgs.Int32">
        <match field="data">16777234</match>
      </input>
      <output topic="/cmd_vel" type="gz.msgs.Twist">
        linear: {x: 0.0}, angular: {z: 0.5}
      </output>
    </plugin>
    <plugin filename="gz-sim-triggered-publisher-system" name="gz::sim::systems::TriggeredPublisher">
      <input topic="/keyboard/keypress" type="gz.msgs.Int32">
        <match field="data">16777236</match>
      </input>
      <output topic="/cmd_vel" type="gz.msgs.Twist">
        linear: {x: 0.0}, angular: {z: -0.5}
      </output>
    </plugin>
    <plugin filename="gz-sim-triggered-publisher-system" name="gz::sim::systems::TriggeredPublisher">
      <input topic="/keyboard/keypress" type="gz.msgs.Int32">
        <match field="data">83</match>
      </input>
      <output topic="/cmd_vel" type="gz.msgs.Twist">
        linear: {x: 0.0}, angular: {z: 0.0}
      </output>
    </plugin>
    <plugin filename="gz-sim-pose-publisher-system" name="gz::sim::systems::PosePublisher">
      <publish_link_pose>False</publish_link_pose>
      <publish_visual_pose>False</publish_visual_pose>
      <publish_collision_pose>False</publish_collision_pose>
      <publish_sensor_pose>False</publish_sensor_pose>
      <publish_model_pose>True</publish_model_pose>
      <publish_nested_model_pose>True</publish_nested_model_pose>
      <use_pose_vector_msg>False</use_pose_vector_msg>
      <update_frequency>3</update_frequency>
      <static_publisher>False</static_publisher>
      <static_update_frequency>3</static_update_frequency>
    </plugin>
    <plugin filename="gz-sim-imu-system" name="gz::sim::systems::Imu">
  </plugin>
    <plugin filename="gz-sim-forcetorque-system" name="gz::sim::systems::ForceTorque">
  </plugin>
  </model>
</sdf>
